Workbook
Name Slicer_Country: #N/A
Name Slicer_Country1: #N/A
Name Slicer_Department: #N/A

Sheet Nz_Staff
C1: Employee Data
C5: Name | D5: Gender | E5: Department | F5: Age | G5: Date Joined | H5: Salary | I5: Rating
C6: Lindy Guillet | D6: Male | E6: Sales | F6: 22 | G6: 44446 | H6: 112780 | I6: Above average
C7: Ambros Murthwaite | D7: Male | E7: Procurement | F7: 46 | G7: 44758 | H7: 70610 | I7: Average
C8: Tatum Hush | D8: Female | E8: Sales | F8: 28 | G8: 44357 | H8: 53240 | I8: Average
C9: Benny Karolovsky | E9: Finance | F9: 37 | G9: 44146 | H9: 115440 | I9: Poor
C10: Hoyt D'Alesco | D10: Male | E10: Sales | F10: 32 | G10: 44465 | H10: 53540 | I10: Average
C11: Halimeda Kuscha | D11: Female | E11: Procurement | F11: 30 | G11: 44861 | H11: 112570 | I11: Average
C12: Erin Androsik | D12: Male | E12: Procurement | F12: 33 | G12: 44701 | H12: 48530 | I12: Above average
C13: Vic Radolf | D13: Female | E13: Website | F13: 24 | G13: 44148 | H13: 62780 | I13: Average
C14: William Reeveley | D14: Male | E14: Website | F14: 33 | G14: 44509 | H14: 53870 | I14: Average
C15: Ewart Laphorn | D15: Female | E15: HR | F15: 27 | G15: 44122 | H15: 119110 | I15: Average
C16: Bev Lashley | D16: Male | E16: Website | F16: 29 | G16: 44180 | H16: 112110 | I16: Poor
C17: Kath Bletsoe | D17: Male | E17: Sales | F17: 25 | G17: 44383 | H17: 65700 | I17: Average
C18: Murry Dryburgh | D18: Male | E18: Website | F18: 37 | G18: 44701 | H18: 69070 | I18: Average
C19: Kaine Padly | D19: Male | E19: Website | F19: 20 | G19: 44459 | H19: 107700 | I19: Average
C20: Kassi Jonson | D20: Female | E20: Website | F20: 32 | G20: 44354 | H20: 43840 | I20: Above average
C21: Simon Kembery | D21: Male | E21: Procurement | F21: 40 | G21: 44263 | H21: 99750 | I21: Average
... C29: Esmaria Denecamp | D29: Male | E29: Finance | F29: 27 | G29: 44567 | H29: 48980 | I29: Average
C30: Curtice Advani | E30: Finance | F30: 30 | G30: 44597 | H30: 64000 | I30: Average
C31: Barr Faughny | D31: Female | E31: Procurement | F31: 42 | G31: 44779 | H31: 75000 | I31: Exceptional
C32: Merrilee Plenty | D32: Female | E32: Website | F32: 40 | G32: 44337 | H32: 87620 | I32: Average
C33: Niall Selesnick | D33: Female | E33: Website | F33: 29 | G33: 44023 | H33: 34980 | I33: Average
C34: Beverie Moffet | D34: Female | E34: Finance | F34: 28 | G34: 44185 | H34: 75970 | I34: Average
C35: Jehu Rudeforth | D35: Female | E35: Finance | F35: 34 | G35: 44612 | H35: 60130 | I35: Average
C36: Camilla Castle | D36: Female | E36: Website | F36: 33 | G36: 44374 | H36: 75480 | I36: Very poor
C37: Roddy Speechley | D37: Male | E37: Procurement | F37: 33 | G37: 44164 | H37: 115920 | I37: Average
C38: Gray Seamon | D38: Female | E38: Sales | F38: 36 | G38: 44494 | H38: 78540 | I38: Average
C39: Madelene Upcott | D39: Male | E39: Procurement | F39: 25 | G39: 44726 | H39: 109190 | I39: Above average
C40: Violante Courtonne | D40: Female | E40: Sales | F40: 34 | G40: 44721 | H40: 49630 | I40: Poor
C41: Bernie Gorges | D41: Female | E41: Procurement | F41: 28 | G41: 44630 | H41: 99970 | I41: Average
C42: Torrance Collier | D42: Female | E42: Website | F42: 33 | G42: 44190 | H42: 96140 | I42: Average
... C67: Wilone O'Kielt | D67: Female | E67: Website | F67: 43 | G67: 45045 | H67: 114870 | I67: Average
C68: Madge McCloughen | E68: Website | F68: 32 | G68: 44774 | H68: 91310 | I68: Average
C69: Janene Hairsine | D69: Female | E69: Procurement | F69: 28 | G69: 44486 | H69: 104770 | I69: Average
C70: Alta Kaszper | D70: Male | E70: Sales | F70: 27 | G70: 44134 | H70: 54970 | I70: Average
C71: Dennison Crosswaite | E71: Website | F71: 26 | G71: 44271 | H71: 90700 | I71: Above average
C72: Oran Buxcy | D72: Female | E72: Sales | F72: 38 | G72: 44329 | H72: 56870 | I72: Above average
C73: Hinda Label | D73: Female | E73: Sales | F73: 25 | G73: 44205 | H73: 92700 | I73: Average
C74: Marney O'Breen | D74: Female | E74: Finance | F74: 21 | G74: 44317 | H74: 65920 | I74: Average
...

Sheet India_Staff
B2: Name | C2: Gender | D2: Age | E2: Rating | F2: Date Joined | G2: Department | H2: Salary
B3: Deepali Charan | C3: Male | D3: 20 | E3: Average | F3: 44122 | G3: Website | H3: 112650
B4: Yagna Sujeev | C4: Female | D4: 32 | E4: Above average | F4: 44293 | G4: Website | H4: 43840
B5: Satyendra Venkatadri | C5: Male | D5: 31 | E5: Average | F5: 44663 | G5: Procurement | H5: 103550
B6: Madhavdas Buhpathi | C6: Female | D6: 32 | E6: Average | F6: 44339 | G6: HR | H6: 45510
B7: Sahila Chandrasekhar | D7: 37 | E7: Poor | F7: 44085 | G7: Finance | H7: 115440
B8: Mirium Seemantini Shivakumar | C8: Female | D8: 38 | E8: Above average | F8: 44268 | G8: Sales | H8: 56870
B9: Purnendu Vijayarangan | C9: Female | D9: 25 | E9: Average | F9: 44144 | G9: Sales | H9: 92700
B10: Rukma Vinita | D10: 32 | E10: Average | F10: 44713 | G10: Website | H10: 91310
B11: Yauvani Tarpa | C11: Male | D11: 33 | E11: Average | F11: 44324 | G11: Sales | H11: 74550
B12: Damayanti Thangavadivelu | C12: Male | D12: 25 | E12: Above average | F12: 44665 | G12: Procurement | H12: 109190
B13: Manjusri Ruchi | C13: Female | D13: 40 | E13: Average | F13: 44320 | G13: Website | H13: 104410
B14: Mithil Nadkarni | C14: Male | D14: 30 | E14: Average | F14: 44544 | G14: Finance | H14: 96800
B15: Ardhendu Abhichandra Jayakar | C15: Male | D15: 28 | E15: Above average | F15: 43980 | G15: Finance | H15: 48170
B16: Akbar Sorabhjee | C16: Male | D16: 21 | E16: Average | F16: 44042 | G16: Procurement | H16: 37920
B17: Bandhula Sathyanna | C17: Male | D17: 34 | E17: Average | F17: 44642 | G17: Procurement | H17: 112650
B18: Daruka Ghazali | C18: Female | D18: 34 | E18: Poor | F18: 44660 | G18: Sales | H18: 49630
B19: Heer Pennathur | C19: Male | D19: 36 | E19: Average | F19: 43958 | G19: Website | H19: 118840
B20: Shekhar Eswara | C20: Male | D20: 30 | E20: Average | F20: 44789 | G20: Website | H20: 69710
B21: Udyan Lanka | C21: Male | D21: 20 | E21: Average | F21: 44683 | G21: Procurement | H21: 79570
B22: Shreela Ramasubraman | C22: Female | D22: 22 | E22: Above average | F22: 44388 | G22: Procurement | H22: 76900
... B53: Indu Varada Sumedh | C53: Female | D53: 28 | E53: Average | F53: 44124 | G53: Finance | H53: 75970
B54: Karuna Pashupathy | D54: 27 | E54: Above average | F54: 44212 | G54: Website | H54: 90700
B55: Mardav Ramaswami | C55: Male | D55: 30 | E55: Average | F55: 44607 | G55: Procurement | H55: 60570
B56: Sarayu Ragunathan | C56: Male | D56: 33 | E56: Average | F56: 44103 | G56: Procurement | H56: 115920
B57: Kevalkumar Solanki | C57: Female | D57: 33 | E57: Average | F57: 44006 | G57: Finance | H57: 65360
B58: Upendra Swati | D58: 30 | E58: Average | F58: 44535 | G58: Finance | H58: 64000
B59: Deepit Ranjana | C59: Female | D59: 34 | E59: Average | F59: 44383 | G59: Finance | H59: 92450
B60: Amal Nimesh | C60: Male | D60: 31 | E60: Average | F60: 44450 | G60: Website | H60: 48950
B61: Kunja Prashanta Vibha | C61: Female | D61: 27 | E61: Average | F61: 44625 | G61: Website | H61: 83750
B62: Godavari Veena | C62: Female | D62: 40 | E62: Average | F62: 44276 | G62: Website | H62: 87620
B63: Devasree Fullara Saurin | C63: Female | D63: 20 | E63: Poor | F63: 44476 | G63: Sales | H63: 68900
B64: Geena Raghavanpillai | C64: Male | D64: 32 | E64: Average | F64: 44403 | G64: Sales | H64: 53540
B65: Rupak Mehra | C65: Male | D65: 28 | E65: Very poor | F65: 44758 | G65: Sales | H65: 43510
B66: Sawini Chandan | C66: Female | D66: 38 | E66: Exceptional | F66: 44316 | G66: Sales | H66: 109160
B67: Baruna Ogale | C67: Male | D67: 40 | E67: Average | F67: 44204 | G67: Procurement | H67: 99750
B68: Jagajeet Viraj | C68: Female | D68: 31 | E68: Average | F68: 44084 | G68: Website | H68: 41980
B69: Kulbhushan Moorthy | C69: Male | D69: 36 | E69: Average | F69: 44272 | G69: Finance | H69: 71380
B70: Ilesh Dasgupta | C70: Male | D70: 27 | E70: Very poor | F70: 44547 | G70: Procurement | H70: 113280
... B98: Madhavdas Buhpathi | C98: Female | D98: 32 | E98: Average | F98: 44339 | G98: HR | H98: 45510
...

Sheet All_STAFF
A1: Name | B1: Gender | C1: Age | D1: Rating | E1: Date Joined | F1: Department | G1: Salary | H1: Country | I1: Tenure | J1: Bonus | K1: Rating_Count | O1: 1 | P1: Bussiness Requerments | T1: Output | U1: Median
A2: Deepali Charan | B2: Male | C2: 20 | D2: Average | E2: 44122 | F2: Website | G2: 112650 | H2: IND | I2: =(TODAY()-All_Staff[[#This Row],[Date Joined]])/365 -> 5.2465753 | J2: =ROUNDUP(IF(All_Staff[[#This Row],[Salary]]>2,3%,2%)*All_Staff[[#This Row],[Salary]],0) -> 3380 | K2: =_xlfn.XLOOKUP(All_Staff[[#This Row],[Rating]],'Salary Vs Rating'!$E$2:$E$6,'Salary Vs Rating'!$F$2:$F$6) -> 3 | P2: Count Of Employee | T2: =COUNTA(All_Staff[Name]) -> 183
A3: Bandhula Sathyanna | B3: Male | C3: 34 | D3: Average | E3: 44642 | F3: Procurement | G3: 112650 | H3: IND | I3: =(TODAY()-All_Staff[[#This Row],[Date Joined]])/365 -> 3.8219178 | J3: =ROUNDUP(IF(All_Staff[[#This Row],[Salary]]>2,3%,2%)*All_Staff[[#This Row],[Salary]],0) -> 3380 | K3: =_xlfn.XLOOKUP(All_Staff[[#This Row],[Rating]],'Salary Vs Rating'!$E$2:$E$6,'Salary Vs Rating'!$F$2:$F$6) -> 3 | P3: Average Salary | T3: =AVERAGE(All_Staff[Salary]) -> 77173.716 | U3: =MEDIAN(All_Staff[Salary]) -> 75000
A4: Krishnakanta Vellanki | B4: Male | C4: 22 | D4: Above average | E4: 44384 | F4: Sales | G4: 112780 | H4: IND | I4: =(TODAY()-All_Staff[[#This Row],[Date Joined]])/365 -> 4.5287671 | J4: =ROUNDUP(IF(All_Staff[[#This Row],[Salary]]>2,3%,2%)*All_Staff[[#This Row],[Salary]],0) -> 3384 | K4: =_xlfn.XLOOKUP(All_Staff[[#This Row],[Rating]],'Salary Vs Rating'!$E$2:$E$6,'Salary Vs Rating'!$F$2:$F$6) -> 4 | P4: Average Age | T4: =AVERAGE(All_Staff[Age]) -> 30.42623 | U4: =MEDIAN(All_Staff[Age]) -> 30
A5: Lindy Guillet | B5: Male | C5: 22 | D5: Above average | E5: 44446 | F5: Sales | G5: 112780 | H5: NZ | I5: =(TODAY()-All_Staff[[#This Row],[Date Joined]])/365 -> 4.3589041 | J5: =ROUNDUP(IF(All_Staff[[#This Row],[Salary]]>2,3%,2%)*All_Staff[[#This Row],[Salary]],0) -> 3384 | K5: =_xlfn.XLOOKUP(All_Staff[[#This Row],[Rating]],'Salary Vs Rating'!$E$2:$E$6,'Salary Vs Rating'!$F$2:$F$6) -> 4 | P5: Average Tenure | T5: =AVERAGE(All_Staff[Tenure]) -> 4.3944307 | U5: =MEDIAN(All_Staff[Tenure]) -> 4.4164384
A6: Mollie Hanway | B6: Male | C6: 20 | D6: Average | E6: 44183 | F6: Website | G6: 112650 | H6: NZ | I6: =(TODAY()-All_Staff[[#This Row],[Date Joined]])/365 -> 5.0794521 | J6: =ROUNDUP(IF(All_Staff[[#This Row],[Salary]]>2,3%,2%)*All_Staff[[#This Row],[Salary]],0) -> 3380 | K6: =_xlfn.XLOOKUP(All_Staff[[#This Row],[Rating]],'Salary Vs Rating'!$E$2:$E$6,'Salary Vs Rating'!$F$2:$F$6) -> 3 | P6: Female Ratio % | T6: =T7/T2 -> 0.46994536
A7: Yagna Sujeev | B7: Female | C7: 32 | D7: Above average | E7: 44293 | F7: Website | G7: 43840 | H7: IND | I7: =(TODAY()-All_Staff[[#This Row],[Date Joined]])/365 -> 4.7780822 | J7: =ROUNDUP(IF(All_Staff[[#This Row],[Salary]]>2,3%,2%)*All_Staff[[#This Row],[Salary]],0) -> 1316 | K7: =_xlfn.XLOOKUP(All_Staff[[#This Row],[Rating]],'Salary Vs Rating'!$E$2:$E$6,'Salary Vs Rating'!$F$2:$F$6) -> 4 | P7: Female Count | T7: =COUNTIFS(All_Staff[Gender],"Female") -> 86
A8: Satyendra Venkatadri | B8: Male | C8: 31 | D8: Average | E8: 44663 | F8: Procurement | G8: 103550 | H8: IND | I8: =(TODAY()-All_Staff[[#This Row],[Date Joined]])/365 -> 3.7643836 | J8: =ROUNDUP(IF(All_Staff[[#This Row],[Salary]]>2,3%,2%)*All_Staff[[#This Row],[Salary]],0) -> 3107 | K8: =_xlfn.XLOOKUP(All_Staff[[#This Row],[Rating]],'Salary Vs Rating'!$E$2:$E$6,'Salary Vs Rating'!$F$2:$F$6) -> 3 | P8: Male Ratio % | T8: =T9/T2 -> 0.4863388
A9: Madhavdas Buhpathi | B9: Female | C9: 32 | D9: Average | E9: 44339 | F9: HR | G9: 45510 | H9: IND | I9: =(TODAY()-All_Staff[[#This Row],[Date Joined]])/365 -> 4.6520548 | J9: =ROUNDUP(IF(All_Staff[[#This Row],[Salary]]>2,3%,2%)*All_Staff[[#This Row],[Salary]],0) -> 1366 | K9: =_xlfn.XLOOKUP(All_Staff[[#This Row],[Rating]],'Salary Vs Rating'!$E$2:$E$6,'Salary Vs Rating'!$F$2:$F$6) -> 3 | P9: Male Count | T9: =COUNTIFS(All_Staff[Gender],"Male") -> 89
A10: Sahila Chandrasekhar | B10: Other | C10: 37 | D10: Poor | E10: 44085 | F10: Finance | G10: 115440 | H10: IND | I10: =(TODAY()-All_Staff[[#This Row],[Date Joined]])/365 -> 5.3479452 | J10: =ROUNDUP(IF(All_Staff[[#This Row],[Salary]]>2,3%,2%)*All_Staff[[#This Row],[Salary]],0) -> 3464 | K10: =_xlfn.XLOOKUP(All_Staff[[#This Row],[Rating]],'Salary Vs Rating'!$E$2:$E$6,'Salary Vs Rating'!$F$2:$F$6) -> 2 | P10: Other Ratio | T10: =T11/T2 -> 0.043715847
A11: Mirium Seemantini Shivakumar | B11: Female | C11: 38 | D11: Above average | E11: 44268 | F11: Sales | G11: 56870 | H11: IND | I11: =(TODAY()-All_Staff[[#This Row],[Date Joined]])/365 -> 4.8465753 | J11: =ROUNDUP(IF(All_Staff[[#This Row],[Salary]]>2,3%,2%)*All_Staff[[#This Row],[Salary]],0) -> 1707 | K11: =_xlfn.XLOOKUP(All_Staff[[#This Row],[Rating]],'Salary Vs Rating'!$E$2:$E$6,'Salary Vs Rating'!$F$2:$F$6) -> 4 | P11: Other Count | T11: =T2-(T9+T7) -> 8
A12: Purnendu Vijayarangan | B12: Female | C12: 25 | D12: Average | E12: 44144 | F12: Sales | G12: 92700 | H12: IND | I12: =(TODAY()-All_Staff[[#This Row],[Date Joined]])/365 -> 5.1863014 | J12: =ROUNDUP(IF(All_Staff[[#This Row],[Salary]]>2,3%,2%)*All_Staff[[#This Row],[Salary]],0) -> 2781 | K12: =_xlfn.XLOOKUP(All_Staff[[#This Row],[Rating]],'Salary Vs Rating'!$E$2:$E$6,'Salary Vs Rating'!$F$2:$F$6) -> 3 | P12: Total Salary(All EMP) | T12: =SUM(All_Staff[Salary]) -> 14122790
A13: Rukma Vinita | B13: Other | C13: 32 | D13: Average | E13: 44713 | F13: Website | G13: 91310 | H13: IND | I13: =(TODAY()-All_Staff[[#This Row],[Date Joined]])/365 -> 3.6273973 | J13: =ROUNDUP(IF(All_Staff[[#This Row],[Salary]]>2,3%,2%)*All_Staff[[#This Row],[Salary]],0) -> 2740 | K13: =_xlfn.XLOOKUP(All_Staff[[#This Row],[Rating]],'Salary Vs Rating'!$E$2:$E$6,'Salary Vs Rating'!$F$2:$F$6) -> 3 | P13: Ration of salary > 90,000$ | T13: =T14/T12 -> 0.47473835
A14: Yauvani Tarpa | B14: Male | C14: 33 | D14: Average | E14: 44324 | F14: Sales | G14: 74550 | H14: IND | I14: =(TODAY()-All_Staff[[#This Row],[Date Joined]])/365 -> 4.6931507 | J14: =ROUNDUP(IF(All_Staff[[#This Row],[Salary]]>2,3%,2%)*All_Staff[[#This Row],[Salary]],0) -> 2237 | K14: =_xlfn.XLOOKUP(All_Staff[[#This Row],[Rating]],'Salary Vs Rating'!$E$2:$E$6,'Salary Vs Rating'!$F$2:$F$6) -> 3 | P14: SUM Of Employee(Salary>90,000$) | T14: =SUMIF(All_Staff[Salary],">90000") -> 6704630
A15: Damayanti Thangavadivelu | B15: Male | C15: 25 | D15: Above average | E15: 44665 | F15: Procurement | G15: 109190 | H15: IND | I15: =(TODAY()-All_Staff[[#This Row],[Date Joined]])/365 -> 3.7589041 | J15: =ROUNDUP(IF(All_Staff[[#This Row],[Salary]]>2,3%,2%)*All_Staff[[#This Row],[Salary]],0) -> 3276 | K15: =_xlfn.XLOOKUP(All_Staff[[#This Row],[Rating]],'Salary Vs Rating'!$E$2:$E$6,'Salary Vs Rating'!$F$2:$F$6) -> 4
A16: Manjusri Ruchi | B16: Female | C16: 40 | D16: Average | E16: 44320 | F16: Website | G16: 104410 | H16: IND | I16: =(TODAY()-All_Staff[[#This Row],[Date Joined]])/365 -> 4.7041096 | J16: =ROUNDUP(IF(All_Staff[[#This Row],[Salary]]>2,3%,2%)*All_Staff[[#This Row],[Salary]],0) -> 3133 | K16: =_xlfn.XLOOKUP(All_Staff[[#This Row],[Rating]],'Salary Vs Rating'!$E$2:$E$6,'Salary Vs Rating'!$F$2:$F$6) -> 3
A17: Mithil Nadkarni | B17: Male | C17: 30 | D17: Average | E17: 44544 | F17: Finance | G17: 96800 | H17: IND | I17: =(TODAY()-All_Staff[[#This Row],[Date Joined]])/365 -> 4.090411 | J17: =ROUNDUP(IF(All_Staff[[#This Row],[Salary]]>2,3%,2%)*All_Staff[[#This Row],[Salary]],0) -> 2904 | K17: =_xlfn.XLOOKUP(All_Staff[[#This Row],[Rating]],'Salary Vs Rating'!$E$2:$E$6,'Salary Vs Rating'!$F$2:$F$6) -> 3 | O17: 2 | P17: Shekhar Eswara
A18: Ardhendu Abhichandra Jayakar | B18: Male | C18: 28 | D18: Above average | E18: 43980 | F18: Finance | G18: 48170 | H18: IND | I18: =(TODAY()-All_Staff[[#This Row],[Date Joined]])/365 -> 5.6356164 | J18: =ROUNDUP(IF(All_Staff[[#This Row],[Salary]]>2,3%,2%)*All_Staff[[#This Row],[Salary]],0) -> 1446 | K18: =_xlfn.XLOOKUP(All_Staff[[#This Row],[Rating]],'Salary Vs Rating'!$E$2:$E$6,'Salary Vs Rating'!$F$2:$F$6) -> 4
A19: Akbar Sorabhjee | B19: Male | C19: 21 | D19: Average | E19: 44042 | F19: Procurement | G19: 37920 | H19: IND | I19: =(TODAY()-All_Staff[[#This Row],[Date Joined]])/365 -> 5.4657534 | J19: =ROUNDUP(IF(All_Staff[[#This Row],[Salary]]>2,3%,2%)*All_Staff[[#This Row],[Salary]],0) -> 1138 | K19: =_xlfn.XLOOKUP(All_Staff[[#This Row],[Rating]],'Salary Vs Rating'!$E$2:$E$6,'Salary Vs Rating'!$F$2:$F$6) -> 3
A20: Daruka Ghazali | B20: Female | C20: 34 | D20: Poor | E20: 44660 | F20: Sales | G20: 49630 | H20: IND | I20: =(TODAY()-All_Staff[[#This Row],[Date Joined]])/365 -> 3.7726027 | J20: =ROUNDUP(IF(All_Staff[[#This Row],[Salary]]>2,3%,2%)*All_Staff[[#This Row],[Salary]],0) -> 1489 | K20: =_xlfn.XLOOKUP(All_Staff[[#This Row],[Rating]],'Salary Vs Rating'!$E$2:$E$6,'Salary Vs Rating'!$F$2:$F$6) -> 2 | P20: Gender | R20: {=TRANSPOSE(_xlfn.XLOOKUP(P17,All_Staff[Name],All_Staff[[Gender]:[Tenure]],"Not Found",0,1))} -> Male
A21: Heer Pennathur | B21: Male | C21: 36 | D21: Average | E21: 43958 | F21: Website | G21: 118840 | H21: IND | I21: =(TODAY()-All_Staff[[#This Row],[Date Joined]])/365 -> 5.6958904 | J21: =ROUNDUP(IF(All_Staff[[#This Row],[Salary]]>2,3%,2%)*All_Staff[[#This Row],[Salary]],0) -> 3566 | K21: =_xlfn.XLOOKUP(All_Staff[[#This Row],[Rating]],'Salary Vs Rating'!$E$2:$E$6,'Salary Vs Rating'!$F$2:$F$6) -> 3 | P21: Age | R21: 30
A22: Shekhar Eswara | B22: Male | C22: 30 | D22: Average | E22: 44789 | F22: Website | G22: 69710 | H22: IND | I22: =(TODAY()-All_Staff[[#This Row],[Date Joined]])/365 -> 3.4191781 | J22: =ROUNDUP(IF(All_Staff[[#This Row],[Salary]]>2,3%,2%)*All_Staff[[#This Row],[Salary]],0) -> 2092 | K22: =_xlfn.XLOOKUP(All_Staff[[#This Row],[Rating]],'Salary Vs Rating'!$E$2:$E$6,'Salary Vs Rating'!$F$2:$F$6) -> 3 | P22: Rating | R22: Average
A23: Udyan Lanka | B23: Male | C23: 20 | D23: Average | E23: 44683 | F23: Procurement | G23: 79570 | H23: IND | I23: =(TODAY()-All_Staff[[#This Row],[Date Joined]])/365 -> 3.709589 | J23: =ROUNDUP(IF(All_Staff[[#This Row],[Salary]]>2,3%,2%)*All_Staff[[#This Row],[Salary]],0) -> 2388 | K23: =_xlfn.XLOOKUP(All_Staff[[#This Row],[Rating]],'Salary Vs Rating'!$E$2:$E$6,'Salary Vs Rating'!$F$2:$F$6) -> 3 | P23: DOB | R23: 44789
A24: Shreela Ramasubraman | B24: Female | C24: 22 | D24: Above average | E24: 44388 | F24: Procurement | G24: 76900 | H24: IND | I24: =(TODAY()-All_Staff[[#This Row],[Date Joined]])/365 -> 4.5178082 | J24: =ROUNDUP(IF(All_Staff[[#This Row],[Salary]]>2,3%,2%)*All_Staff[[#This Row],[Salary]],0) -> 2307 | K24: =_xlfn.XLOOKUP(All_Staff[[#This Row],[Rating]],'Salary Vs Rating'!$E$2:$E$6,'Salary Vs Rating'!$F$2:$F$6) -> 4 | P24: Department | R24: Website
A25: Sanchali Shirish | B25: Male | C25: 27 | D25: Average | E25: 44073 | F25: Sales | G25: 54970 | H25: IND | I25: =(TODAY()-All_Staff[[#This Row],[Date Joined]])/365 -> 5.3808219 | J25: =ROUNDUP(IF(All_Staff[[#This Row],[Salary]]>2,3%,2%)*All_Staff[[#This Row],[Salary]],0) -> 1650 | K25: =_xlfn.XLOOKUP(All_Staff[[#This Row],[Rating]],'Salary Vs Rating'!$E$2:$E$6,'Salary Vs Rating'!$F$2:$F$6) -> 3 | P25: Salary | R25: 69710
A26: Gangadutt Ragha | B26: Male | C26: 37 | D26: Poor | E26: 44277 | F26: Website | G26: 88050 | H26: IND | I26: =(TODAY()-All_Staff[[#This Row],[Date Joined]])/365 -> 4.8219178 | J26: =ROUNDUP(IF(All_Staff[[#This Row],[Salary]]>2,3%,2%)*All_Staff[[#This Row],[Salary]],0) -> 2642 | K26: =_xlfn.XLOOKUP(All_Staff[[#This Row],[Rating]],'Salary Vs Rating'!$E$2:$E$6,'Salary Vs Rating'!$F$2:$F$6) -> 2 | P26: Country | R26: IND
A27: Waheeda Vasuman | B27: Male | C27: 43 | D27: Average | E27: 44558 | F27: Sales | G27: 36040 | H27: IND | I27: =(TODAY()-All_Staff[[#This Row],[Date Joined]])/365 -> 4.0520548 | J27: =ROUNDUP(IF(All_Staff[[#This Row],[Salary]]>2,3%,2%)*All_Staff[[#This Row],[Salary]],0) -> 1082 | K27: =_xlfn.XLOOKUP(All_Staff[[#This Row],[Rating]],'Salary Vs Rating'!$E$2:$E$6,'Salary Vs Rating'!$F$2:$F$6) -> 3 | P27: Tenure | R27: 3.4191781
A28: Nanak Sapna | B28: Female | C28: 42 | D28: Exceptional | E28: 44718 | F28: Procurement | G28: 75000 | H28: IND | I28: =(TODAY()-All_Staff[[#This Row],[Date Joined]])/365 -> 3.6136986 | J28: =ROUNDUP(IF(All_Staff[[#This Row],[Salary]]>2,3%,2%)*All_Staff[[#This Row],[Salary]],0) -> 2250 | K28: =_xlfn.XLOOKUP(All_Staff[[#This Row],[Rating]],'Salary Vs Rating'!$E$2:$E$6,'Salary Vs Rating'!$F$2:$F$6) -> 5
A29: Shobhana Samuel | B29: Male | C29: 35 | D29: Average | E29: 44666 | F29: Procurement | G29: 40400 | H29: IND | I29: =(TODAY()-All_Staff[[#This Row],[Date Joined]])/365 -> 3.7561644 | J29: =ROUNDUP(IF(All_Staff[[#This Row],[Salary]]>2,3%,2%)*All_Staff[[#This Row],[Salary]],0) -> 1212 | K29: =_xlfn.XLOOKUP(All_Staff[[#This Row],[Rating]],'Salary Vs Rating'!$E$2:$E$6,'Salary Vs Rating'!$F$2:$F$6) -> 3
A30: Amlankusum Rajabhushan | B30: Male | C30: 24 | D30: Average | E30: 44625 | F30: Website | G30: 100420 | H30: IND | I30: =(TODAY()-All_Staff[[#This Row],[Date Joined]])/365 -> 3.8684932 | J30: =ROUNDUP(IF(All_Staff[[#This Row],[Salary]]>2,3%,2%)*All_Staff[[#This Row],[Salary]],0) -> 3013 | K30: =_xlfn.XLOOKUP(All_Staff[[#This Row],[Rating]],'Salary Vs Rating'!$E$2:$E$6,'Salary Vs Rating'!$F$2:$F$6) -> 3
A31: Pratigya Rema | B31: Female | C31: 31 | D31: Average | E31: 44604 | F31: Website | G31: 58100 | H31: IND | I31: =(TODAY()-All_Staff[[#This Row],[Date Joined]])/365 -> 3.9260274 | J31: =ROUNDUP(IF(All_Staff[[#This Row],[Salary]]>2,3%,2%)*All_Staff[[#This Row],[Salary]],0) -> 1743 | K31: =_xlfn.XLOOKUP(All_Staff[[#This Row],[Rating]],'Salary Vs Rating'!$E$2:$E$6,'Salary Vs Rating'!$F$2:$F$6) -> 3
A32: Ramnath Ravuri | B32: Female | C32: 44 | D32: Average | E32: 44985 | F32: Website | G32: 114870 | H32: IND | I32: =(TODAY()-All_Staff[[#This Row],[Date Joined]])/365 -> 2.8821918 | J32: =ROUNDUP(IF(All_Staff[[#This Row],[Salary]]>2,3%,2%)*All_Staff[[#This Row],[Salary]],0) -> 3447 | K32: =_xlfn.XLOOKUP(All_Staff[[#This Row],[Rating]],'Salary Vs Rating'!$E$2:$E$6,'Salary Vs Rating'!$F$2:$F$6) -> 3
A33: Prerana Nishita | B33: Female | C33: 32 | D33: Average | E33: 44549 | F33: Procurement | G33: 41570 | H33: IND | I33: =(TODAY()-All_Staff[[#This Row],[Date Joined]])/365 -> 4.0767123 | J33: =ROUNDUP(IF(All_Staff[[#This Row],[Salary]]>2,3%,2%)*All_Staff[[#This Row],[Salary]],0) -> 1248 | K33: =_xlfn.XLOOKUP(All_Staff[[#This Row],[Rating]],'Salary Vs Rating'!$E$2:$E$6,'Salary Vs Rating'!$F$2:$F$6) -> 3
A34: Makshi Vinutha | B34: Female | C34: 30 | D34: Average | E34: 44800 | F34: Procurement | G34: 112570 | H34: IND | I34: =(TODAY()-All_Staff[[#This Row],[Date Joined]])/365 -> 3.3890411 | J34: =ROUNDUP(IF(All_Staff[[#This Row],[Salary]]>2,3%,2%)*All_Staff[[#This Row],[Salary]],0) -> 3378 | K34: =_xlfn.XLOOKUP(All_Staff[[#This Row],[Rating]],'Salary Vs Rating'!$E$2:$E$6,'Salary Vs Rating'!$F$2:$F$6) -> 3
A35: Shiuli Sapna | B35: Male | C35: 26 | D35: Average | E35: 44164 | F35: Procurement | G35: 47360 | H35: IND | I35: =(TODAY()-All_Staff[[#This Row],[Date Joined]])/365 -> 5.1315068 | J35: =ROUNDUP(IF(All_Staff[[#This Row],[Salary]]>2,3%,2%)*All_Staff[[#This Row],[Salary]],0) -> 1421 | K35: =_xlfn.XLOOKUP(All_Staff[[#This Row],[Rating]],'Salary Vs Rating'!$E$2:$E$6,'Salary Vs Rating'!$F$2:$F$6) -> 3
A36: Agrata Rajarama | B36: Female | C36: 21 | D36: Average | E36: 44256 | F36: Finance | G36: 65920 | H36: IND | I36: =(TODAY()-All_Staff[[#This Row],[Date Joined]])/365 -> 4.8794521 | J36: =ROUNDUP(IF(All_Staff[[#This Row],[Salary]]>2,3%,2%)*All_Staff[[#This Row],[Salary]],0) -> 1978 | K36: =_xlfn.XLOOKUP(All_Staff[[#This Row],[Rating]],'Salary Vs Rating'!$E$2:$E$6,'Salary Vs Rating'!$F$2:$F$6) -> 3
A37: Vasu Nandin | B37: Female | C37: 28 | D37: Average | E37: 44571 | F37: Procurement | G37: 99970 | H37: IND | I37: =(TODAY()-All_Staff[[#This Row],[Date Joined]])/365 -> 4.0164384 | J37: =ROUNDUP(IF(All_Staff[[#This Row],[Salary]]>2,3%,2%)*All_Staff[[#This Row],[Salary]],0) -> 3000 | K37: =_xlfn.XLOOKUP(All_Staff[[#This Row],[Rating]],'Salary Vs Rating'!$E$2:$E$6,'Salary Vs Rating'!$F$2:$F$6) -> 3
A38: Bhuvan Pals | B38: Female | C38: 25 | D38: Above average | E38: 44633 | F38: Website | G38: 80700 | H38: IND | I38: =(TODAY()-All_Staff[[#This Row],[Date Joined]])/365 -> 3.8465753 | J38: =ROUNDUP(IF(All_Staff[[#This Row],[Salary]]>2,3%,2%)*All_Staff[[#This Row],[Salary]],0) -> 2421 | K38: =_xlfn.XLOOKUP(All_Staff[[#This Row],[Rating]],'Salary Vs Rating'!$E$2:$E$6,'Salary Vs Rating'!$F$2:$F$6) -> 4
A39: Gumwant Veera | B39: Male | C39: 24 | D39: Poor | E39: 44375 | F39: Finance | G39: 52610 | H39: IND | I39: =(TODAY()-All_Staff[[#This Row],[Date Joined]])/365 -> 4.5534247 | J39: =ROUNDUP(IF(All_Staff[[#This Row],[Salary]]>2,3%,2%)*All_Staff[[#This Row],[Salary]],0) -> 1579 | K39: =_xlfn.XLOOKUP(All_Staff[[#This Row],[Rating]],'Salary Vs Rating'!$E$2:$E$6,'Salary Vs Rating'!$F$2:$F$6) -> 2
... A184: Zach Polon | B184: Male | C184: 26 | D184: Average | E184: 44411 | F184: Procurement | G184: 53540 | H184: NZ | I184: =(TODAY()-All_Staff[[#This Row],[Date Joined]])/365 -> 4.4547945 | J184: =ROUNDUP(IF(All_Staff[[#This Row],[Salary]]>2,3%,2%)*All_Staff[[#This Row],[Salary]],0) -> 1607 | K184: =_xlfn.XLOOKUP(All_Staff[[#This Row],[Rating]],'Salary Vs Rating'!$E$2:$E$6,'Salary Vs Rating'!$F$2:$F$6) -> 3
...

Sheet Info_Founder_2.0
A1: 3
B3: Department | E3: Website
B5: Name | C5: Gender | D5: Age | E5: Rating | F5: Date Joined | G5: Department | H5: Salary | I5: Country | J5: Tenure | K5: DOJ
B6: {=_xlfn._xlws.SORT(_xlfn._xlws.FILTER(All_Staff[],All_Staff[Department]=E3),5,-1)} -> Wilone O'Kielt | C6: Female | D6: 43 | E6: Average | F6: 45045 | G6: Website | H6: 114870 | I6: NZ | J6: 2.7178082 | K6: 3447 | L6: 3
B7: Ramnath Ravuri | C7: Female | D7: 44 | E7: Average | F7: 44985 | G7: Website | H7: 114870 | I7: IND | J7: 2.8821918 | K7: 3447 | L7: 3
B8: Myer McCory | C8: Male | D8: 30 | E8: Average | F8: 44850 | G8: Website | H8: 69710 | I8: NZ | J8: 3.2520548 | K8: 2092 | L8: 3
B9: Shekhar Eswara | C9: Male | D9: 30 | E9: Average | F9: 44789 | G9: Website | H9: 69710 | I9: IND | J9: 3.4191781 | K9: 2092 | L9: 3
B10: Madge McCloughen | C10: Other | D10: 32 | E10: Average | F10: 44774 | G10: Website | H10: 91310 | I10: NZ | J10: 3.460274 | K10: 2740 | L10: 3
B11: Rukma Vinita | C11: Other | D11: 32 | E11: Average | F11: 44713 | G11: Website | H11: 91310 | I11: IND | J11: 3.6273973 | K11: 2740 | L11: 3
B12: Murry Dryburgh | C12: Male | D12: 37 | E12: Average | F12: 44701 | G12: Website | H12: 69070 | I12: NZ | J12: 3.660274 | K12: 2073 | L12: 3
B13: Van Tuxwell | C13: Female | D13: 25 | E13: Above average | F13: 44694 | G13: Website | H13: 80700 | I13: NZ | J13: 3.6794521 | K13: 2421 | L13: 4
B14: Agnes Collicott | C14: Female | D14: 27 | E14: Average | F14: 44686 | G14: Website | H14: 83750 | I14: NZ | J14: 3.7013699 | K14: 2513 | L14: 3
B15: Collin Jagson | C15: Male | D15: 24 | E15: Average | F15: 44686 | G15: Website | H15: 100420 | I15: NZ | J15: 3.7013699 | K15: 3013 | L15: 3
B16: Gretchen Callow | C16: Female | D16: 21 | E16: Average | F16: 44678 | G16: Website | H16: 33920 | I16: NZ | J16: 3.7232877 | K16: 1018 | L16: 3
B17: Brien Boise | C17: Female | D17: 31 | E17: Average | F17: 44663 | G17: Website | H17: 58100 | I17: NZ | J17: 3.7643836 | K17: 1743 | L17: 3
B18: Jaishree Atasi Yavatkar | C18: Male | D18: 37 | E18: Average | F18: 44640 | G18: Website | H18: 69070 | I18: IND | J18: 3.8273973 | K18: 2073 | L18: 3
... B59: Heer Pennathur | C59: Male | D59: 36 | E59: Average | F59: 43958 | G59: Website | H59: 118840 | I59: IND | J59: 5.6958904 | K59: 3566 | L59: 3
B60: Total,Average | D60: =AVERAGE(D6:D59) -> 30.666667 | H60: =SUM(H6:H59) -> 4252700 | J60: =AVERAGE(J6:J59) -> 4.468138

Sheet Male Vs. Female
A1: 4
A3: Male Vs. Female
B5: Column Labels
A6: Values | B6: Female | C6: Male | D6: Grand Total
A7: Count of Name | B7: 86 | C7: 89 | D7: 175
A8: Average of Age | B8: 31.406977 | C8: 29.393258 | D8: 30.382857
A9: Sum of Salary | B9: 6732440 | C9: 6667450 | D9: 13399890
A10: Average of Tenure | B10: 4.3970054 | C10: 4.3879021 | D10: 4.3923757

Sheet Salary_Spread

Sheet Salary Vs Rating
A1: Row Labels | B1: Count of Name | C1: Average of Salary | E1: Rating | F1: Rating Number
A2: Exceptional | B2: 2 | C2: 92080 | E2: Exceptional | F2: 5
A3: Above average | B3: 15 | C3: 72953.333 | E3: Above average | F3: 4
A4: Average | B4: 82 | C4: 78746.463 | E4: Average | F4: 3
A5: Poor | B5: 10 | C5: 78999 | E5: Poor | F5: 2
A6: Very poor | B6: 3 | C6: 77423.333 | E6: Very poor | F6: 1
A7: Grand Total | B7: 112 | C7: 78195.804

Sheet Employee_Trend
B1: Row Labels | C1: Count of Name
B2: 2020
B3: May | C3: 5
B4: Jun | C4: 1
B5: Jul | C5: 3
B6: Aug | C6: 2
B7: Sep | C7: 5
B8: Oct | C8: 5
B9: Nov | C9: 3
B10: Dec | C10: 3
B11: 2021 | C11: 49
B12: 2022 | C12: 35
B13: 2023 | C13: 1
B14: Grand Total | C14: 112

Sheet Report_Cart
H5: HeadCount By Departmet
H7: =COUNTIF(All_Staff[Country],"NZ") -> 91 | J7: =COUNTIFS(All_Staff[Country],"NZ",All_Staff[Gender], "Female")/H7 -> 0.47252747 | L7: =AVERAGEIFS(All_Staff[Salary],All_Staff[Country],"NZ") -> 76978.791 | N7: =COUNTIF(All_Staff[Country],"IND") -> 92 | P7: =COUNTIFS(All_Staff[Country],"IND",All_Staff[Gender], "Female")/N7 -> 0.4673913 | R7: =AVERAGEIFS(All_Staff[Salary],All_Staff[Country],"IND") -> 77366.522
H8: NEWZLAND | N8: INDIA

Sheet Pivot_Tables
B1: Country | C1: All | E1: Country | F1: All | H1: Country | I1: All
B3: Row Labels | C3: Count of Name | E3: Row Labels | F3: Count of Name | H3: Row Labels | I3: Count of Name
B4: Finance | C4: 38 | E4: Procurement | F4: 55 | H4: Procurement | I4: 55
B5: HR | C5: 8 | E5: Website | F5: 54 | H5: Website | I5: 54
B6: Procurement | C6: 55 | E6: Finance | F6: 38 | H6: Finance | I6: 38
B7: Sales | C7: 28 | E7: Sales | F7: 28 | H7: Sales | I7: 28
B8: Website | C8: 54 | E8: HR | F8: 8 | H8: HR | I8: 8
B9: Grand Total | C9: 183 | E9: Grand Total | F9: 183 | H9: Grand Total | I9: 183
